<robot name="hitter">
  <material name="blue">
    <color rgba="0 0 0.8 1"/>
  </material>
  <material name="red">
    <color rgba="1 0 0 1"/>
  </material>
  <material name="white">
    <color rgba="1 1 1 1"/>
  </material>

      <link name="base_link">
<inertial>
         <origin xyz ="0 0 0" rpy="0 0 0"/>
         <mass value="5.0"/>
         <inertia
           ixx="0.003159"
           iyy="0.003159"
           izz="0.00625"
           ixy="0.0"
           ixz="0.0"
           iyz="0.0" />        
        </inertial>
        <visual>
          <geometry>
            <cylinder length="0.009" radius="0.05"/>
          </geometry>
     <origin xyz ="0 0 0" rpy="0 0 0"/>
     <material name="red"/>
        </visual>
     <collision>
         <geometry>
            <cylinder length="0.009" radius="0.05"/>
          </geometry>
     <origin xyz ="0 0 0" rpy="0 0 0"/>
       </collision>
      </link>

   <link name="right_leg">
<inertial>
         <origin xyz ="0.21 0 0.00145" rpy="0 0 0"/>
         <mass value="0.5"/>
         <inertia
           ixx="0.00010833"
           iyy="0.007354"
           izz="0.007454"
           ixy="0.0"
           ixz="0.00021364"
           iyz="0.0" />        
        </inertial>
       <visual>
         <geometry>
          <box size="0.42 0.05 0.02"/>
         </geometry>
    <origin xyz ="0.21 0 0.00145" rpy="0 0 0"/>
     <material name="blue"/>
       </visual>
    <collision>
      <geometry>
         <box size="0.42 0.05 0.01"/>
         </geometry>
    <origin xyz ="0.21 0 0.00145" rpy="0 0 0"/>
       </collision>
     </link>
   
     <joint name="base_to_right_leg" type="revolute">
         <axis xyz="0 0 1"/>
        <limit effort="100.0" lower="-3.14" upper="3.14" velocity="0.9"/>
       <parent link="base_link"/>
       <child link="right_leg"/>
    <origin xyz="0 0 0.014"/>
     </joint>
   
   </robot>
